Workbook

Sheet Хяналтын самбар
B2: ХЯНАЛТЫН САМБАР
B6: 1. НЭГДСЭН ҮЗҮҮЛЭЛТ
B7: Үзүүлэлт | C7: Веб систем | D7: Мобайл апп | E7: Нийт
B8: Нийт ажил | C8: =COUNT('Веб систем'!$A$5:$A$157) -> 151 | D8: =COUNT('Мобайл апп'!$A$5:$A$86) -> 82 | E8: =C8+D8 -> 233
B9: Дууссан | C9: =COUNTIF('Веб систем'!$I$5:$I$157,"Дууссан") -> 80 | D9: =COUNTIF('Мобайл апп'!$I$5:$I$86,"Дууссан") -> 11 | E9: =C9+D9 -> 91
B10: Тестэд | C10: =COUNTIF('Веб систем'!$I$5:$I$157,"Тестэд") -> 0 | D10: =COUNTIF('Мобайл апп'!$I$5:$I$86,"Тестэд") -> 0 | E10: =C10+D10 -> 0
B11: Хийгдэж байна | C11: =COUNTIF('Веб систем'!$I$5:$I$157,"Хийгдэж байна") -> 9 | D11: =COUNTIF('Мобайл апп'!$I$5:$I$86,"Хийгдэж байна") -> 1 | E11: =C11+D11 -> 10
B12: Эхлээгүй | C12: =COUNTIF('Веб систем'!$I$5:$I$157,"Эхлээгүй") -> 40 | D12: =COUNTIF('Мобайл апп'!$I$5:$I$86,"Эхлээгүй") -> 59 | E12: =C12+D12 -> 99
B13: Саатсан | C13: =COUNTIF('Веб систем'!$I$5:$I$157,"Саатсан") -> 22 | D13: =COUNTIF('Мобайл апп'!$I$5:$I$86,"Саатсан") -> 11 | E13: =C13+D13 -> 33
B14: Дундаж гүйцэтгэл | C14: =IFERROR(AVERAGE('Веб систем'!$J$5:$J$157),0) -> 0.51111111 | D14: =IFERROR(AVERAGE('Мобайл апп'!$J$5:$J$86),0) -> 0.1402439 | E14: =IFERROR((SUM('Веб систем'!$J$5:$J$157)+SUM('Мобайл апп'!$J$5:$J$86))/(COUNT('Веб систем'!$J$5:$J$157)+COUNT('Мобайл апп'!$J$5:$J$86)),0) -> 0.38170213
B15: Хугацаа хэтэрсэн | C15: =SUMPRODUCT(('Веб систем'!$H$5:$H$157<>"")*('Веб систем'!$H$5:$H$157<TODAY())*('Веб систем'!$I$5:$I$157<>"Дууссан")*('Веб систем'!$I$5:$I$157<>"Хамаарахгүй")) -> 58 | D15: =SUMPRODUCT(('Мобайл апп'!$H$5:$H$86<>"")*('Мобайл апп'!$H$5:$H$86<TODAY())*('Мобайл апп'!$I$5:$I$86<>"Дууссан")*('Мобайл апп'!$I$5:$I$86<>"Хамаарахгүй")) -> 49 | E15: =C15+D15 -> 107
B17: 2. ХАРИУЦАХ ТАЛААР
B18: Тал | C18: Нийт ажил | D18: Дууссан | E18: Хийгдэж байна | F18: Эхлээгүй | G18: Дундаж гүйцэтгэл
B19: ITsystem | C19: =COUNTIF('Веб систем'!$F$5:$F$157,"ITsystem")+COUNTIF('Мобайл апп'!$F$5:$F$86,"ITsystem") -> 171 | D19: =COUNTIFS('Веб систем'!$F$5:$F$157,"ITsystem",'Веб систем'!$I$5:$I$157,"Дууссан")+COUNTIFS('Мобайл апп'!$F$5:$F$86,"ITsystem",'Мобайл апп'!$I$5:$I$86,"Дууссан") -> 80 | E19: =COUNTIFS('Веб систем'!$F$5:$F$157,"ITsystem",'Веб систем'!$I$5:$I$157,"Хийгдэж байна")+COUNTIFS('Мобайл апп'!$F$5:$F$86,"ITsystem",'Мобайл апп'!$I$5:$I$86,"Хийгдэж байна") -> 10 | F19: =COUNTIFS('Веб систем'!$F$5:$F$157,"ITsystem",'Веб систем'!$I$5:$I$157,"Эхлээгүй")+COUNTIFS('Мобайл апп'!$F$5:$F$86,"ITsystem",'Мобайл апп'!$I$5:$I$86,"Эхлээгүй") -> 66 | G19: =IFERROR((SUMIF('Веб систем'!$F$5:$F$157,"ITsystem",'Веб систем'!$J$5:$J$157)+SUMIF('Мобайл апп'!$F$5:$F$86,"ITsystem",'Мобайл апп'!$J$5:$J$86))/(COUNTIF('Веб систем'!$F$5:$F$157,"ITsystem")+COUNTIF('Мобайл апп'!$F$5:$F$86,"ITsystem")),0) -> 0.47192982
B20: ЗСҮТ | C20: =COUNTIF('Веб систем'!$F$5:$F$157,"ЗСҮТ")+COUNTIF('Мобайл апп'!$F$5:$F$86,"ЗСҮТ") -> 62 | D20: =COUNTIFS('Веб систем'!$F$5:$F$157,"ЗСҮТ",'Веб систем'!$I$5:$I$157,"Дууссан")+COUNTIFS('Мобайл апп'!$F$5:$F$86,"ЗСҮТ",'Мобайл апп'!$I$5:$I$86,"Дууссан") -> 11 | E20: =COUNTIFS('Веб систем'!$F$5:$F$157,"ЗСҮТ",'Веб систем'!$I$5:$I$157,"Хийгдэж байна")+COUNTIFS('Мобайл апп'!$F$5:$F$86,"ЗСҮТ",'Мобайл апп'!$I$5:$I$86,"Хийгдэж байна") -> 0 | F20: =COUNTIFS('Веб систем'!$F$5:$F$157,"ЗСҮТ",'Веб систем'!$I$5:$I$157,"Эхлээгүй")+COUNTIFS('Мобайл апп'!$F$5:$F$86,"ЗСҮТ",'Мобайл апп'!$I$5:$I$86,"Эхлээгүй") -> 33 | G20: =IFERROR((SUMIF('Веб систем'!$F$5:$F$157,"ЗСҮТ",'Веб систем'!$J$5:$J$157)+SUMIF('Мобайл апп'!$F$5:$F$86,"ЗСҮТ",'Мобайл апп'!$J$5:$J$86))/(COUNTIF('Веб систем'!$F$5:$F$157,"ЗСҮТ")+COUNTIF('Мобайл апп'!$F$5:$F$86,"ЗСҮТ")),0) -> 0.11290323
B22: 3. ҮЕ ШАТААР
B23: Төсөл / Үе шат | C23: Нийт ажил | D23: Дууссан | E23: Дундаж гүйцэтгэл | F23: Хугацаа
B24: ВЕБ СИСТЕМ
B25: 1. Шаардлагын судалгаа, шинжилгээ | C25: =COUNTIF('Веб систем'!$B$5:$B$157,"1. Шаардлагын судалгаа, шинжилгээ") -> 9 | D25: =COUNTIFS('Веб систем'!$B$5:$B$157,"1. Шаардлагын судалгаа, шинжилгээ",'Веб систем'!$I$5:$I$157,"Дууссан") -> 9 | E25: =IFERROR(SUMIF('Веб систем'!$B$5:$B$157,"1. Шаардлагын судалгаа, шинжилгээ",'Веб систем'!$J$5:$J$157)/COUNTIF('Веб систем'!$B$5:$B$157,"1. Шаардлагын судалгаа, шинжилгээ"),0) -> 1 | F25: 05-14 – 05-27
B26: 2. Архитектур, дизайн боловсруулах | C26: =COUNTIF('Веб систем'!$B$5:$B$157,"2. Архитектур, дизайн боловсруулах") -> 4 | D26: =COUNTIFS('Веб систем'!$B$5:$B$157,"2. Архитектур, дизайн боловсруулах",'Веб систем'!$I$5:$I$157,"Дууссан") -> 4 | E26: =IFERROR(SUMIF('Веб систем'!$B$5:$B$157,"2. Архитектур, дизайн боловсруулах",'Веб систем'!$J$5:$J$157)/COUNTIF('Веб систем'!$B$5:$B$157,"2. Архитектур, дизайн боловсруулах"),0) -> 1 | F26: 05-28 – 06-06
B27: 3. Өгөгдлийн сангийн загвар, маягтын бүтэц | C27: =COUNTIF('Веб систем'!$B$5:$B$157,"3. Өгөгдлийн сангийн загвар, маягтын бүтэц") -> 7 | D27: =COUNTIFS('Веб систем'!$B$5:$B$157,"3. Өгөгдлийн сангийн загвар, маягтын бүтэц",'Веб систем'!$I$5:$I$157,"Дууссан") -> 6 | E27: =IFERROR(SUMIF('Веб систем'!$B$5:$B$157,"3. Өгөгдлийн сангийн загвар, маягтын бүтэц",'Веб систем'!$J$5:$J$157)/COUNTIF('Веб систем'!$B$5:$B$157,"3. Өгөгдлийн сангийн загвар, маягтын бүтэц"),0) -> 0.71428571 | F27: 06-07 – 07-06
B28: 4. Цахим маягт, модуль хөгжүүлэлт | C28: =COUNTIF('Веб систем'!$B$5:$B$157,"4. Цахим маягт, модуль хөгжүүлэлт") -> 108 | D28: =COUNTIFS('Веб систем'!$B$5:$B$157,"4. Цахим маягт, модуль хөгжүүлэлт",'Веб систем'!$I$5:$I$157,"Дууссан") -> 61 | E28: =IFERROR(SUMIF('Веб систем'!$B$5:$B$157,"4. Цахим маягт, модуль хөгжүүлэлт",'Веб систем'!$J$5:$J$157)/COUNTIF('Веб систем'!$B$5:$B$157,"4. Цахим маягт, модуль хөгжүүлэлт"),0) -> 0.50925926 | F28: 07-07 – 09-01
B29: 5. Тестлэлт, чанарын баталгаажуулалт | C29: =COUNTIF('Веб систем'!$B$5:$B$157,"5. Тестлэлт, чанарын баталгаажуулалт") -> 9 | D29: =COUNTIFS('Веб систем'!$B$5:$B$157,"5. Тестлэлт, чанарын баталгаажуулалт",'Веб систем'!$I$5:$I$157,"Дууссан") -> 0 | E29: =IFERROR(SUMIF('Веб систем'!$B$5:$B$157,"5. Тестлэлт, чанарын баталгаажуулалт",'Веб систем'!$J$5:$J$157)/COUNTIF('Веб систем'!$B$5:$B$157,"5. Тестлэлт, чанарын баталгаажуулалт"),0) -> 0.18888889 | F29: 09-01 – 09-10
B30: 6. Хэрэглэгчийн сургалт, баримт бичиг | C30: =COUNTIF('Веб систем'!$B$5:$B$157,"6. Хэрэглэгчийн сургалт, баримт бичиг") -> 6 | D30: =COUNTIFS('Веб систем'!$B$5:$B$157,"6. Хэрэглэгчийн сургалт, баримт бичиг",'Веб систем'!$I$5:$I$157,"Дууссан") -> 0 | E30: =IFERROR(SUMIF('Веб систем'!$B$5:$B$157,"6. Хэрэглэгчийн сургалт, баримт бичиг",'Веб систем'!$J$5:$J$157)/COUNTIF('Веб систем'!$B$5:$B$157,"6. Хэрэглэгчийн сургалт, баримт бичиг"),0) -> 0.05 | F30: 08-28 – 09-03
B31: 7. Систем ашиглалтад өгөх | C31: =COUNTIF('Веб систем'!$B$5:$B$157,"7. Систем ашиглалтад өгөх") -> 5 | D31: =COUNTIFS('Веб систем'!$B$5:$B$157,"7. Систем ашиглалтад өгөх",'Веб систем'!$I$5:$I$157,"Дууссан") -> 0 | E31: =IFERROR(SUMIF('Веб систем'!$B$5:$B$157,"7. Систем ашиглалтад өгөх",'Веб систем'!$J$5:$J$157)/COUNTIF('Веб систем'!$B$5:$B$157,"7. Систем ашиглалтад өгөх"),0) -> 0.24 | F31: 09-10 – 09-14
B32: 8. Баталгаат хугацааны дэмжлэг | C32: =COUNTIF('Веб систем'!$B$5:$B$157,"8. Баталгаат хугацааны дэмжлэг") -> 3 | D32: =COUNTIFS('Веб систем'!$B$5:$B$157,"8. Баталгаат хугацааны дэмжлэг",'Веб систем'!$I$5:$I$157,"Дууссан") -> 0 | E32: =IFERROR(SUMIF('Веб систем'!$B$5:$B$157,"8. Баталгаат хугацааны дэмжлэг",'Веб систем'!$J$5:$J$157)/COUNTIF('Веб систем'!$B$5:$B$157,"8. Баталгаат хугацааны дэмжлэг"),0) -> 0 | F32: 2026-09-15 – 2027-09-14
B33: МОБАЙЛ АПП
B34: 1. Шинжилгээ, төлөвлөлт | C34: =COUNTIF('Мобайл апп'!$B$5:$B$86,"1. Шинжилгээ, төлөвлөлт") -> 6 | D34: =COUNTIFS('Мобайл апп'!$B$5:$B$86,"1. Шинжилгээ, төлөвлөлт",'Мобайл апп'!$I$5:$I$86,"Дууссан") -> 5 | E34: =IFERROR(SUMIF('Мобайл апп'!$B$5:$B$86,"1. Шинжилгээ, төлөвлөлт",'Мобайл апп'!$J$5:$J$86)/COUNTIF('Мобайл апп'!$B$5:$B$86,"1. Шинжилгээ, төлөвлөлт"),0) -> 0.83333333 | F34: 07-03 – 07-12
B35: 2. Архитектур, UI/UX дизайн | C35: =COUNTIF('Мобайл апп'!$B$5:$B$86,"2. Архитектур, UI/UX дизайн") -> 5 | D35: =COUNTIFS('Мобайл апп'!$B$5:$B$86,"2. Архитектур, UI/UX дизайн",'Мобайл апп'!$I$5:$I$86,"Дууссан") -> 4 | E35: =IFERROR(SUMIF('Мобайл апп'!$B$5:$B$86,"2. Архитектур, UI/UX дизайн",'Мобайл апп'!$J$5:$J$86)/COUNTIF('Мобайл апп'!$B$5:$B$86,"2. Архитектур, UI/UX дизайн"),0) -> 0.8 | F35: 07-10 – 07-24
B36: 3. Суурь систем хөгжүүлэлт | C36: =COUNTIF('Мобайл апп'!$B$5:$B$86,"3. Суурь систем хөгжүүлэлт") -> 16 | D36: =COUNTIFS('Мобайл апп'!$B$5:$B$86,"3. Суурь систем хөгжүүлэлт",'Мобайл апп'!$I$5:$I$86,"Дууссан") -> 2 | E36: =IFERROR(SUMIF('Мобайл апп'!$B$5:$B$86,"3. Суурь систем хөгжүүлэлт",'Мобайл апп'!$J$5:$J$86)/COUNTIF('Мобайл апп'!$B$5:$B$86,"3. Суурь систем хөгжүүлэлт"),0) -> 0.15625 | F36: 07-22 – 08-16
B37: 4. Эмчийн модуль | C37: =COUNTIF('Мобайл апп'!$B$5:$B$86,"4. Эмчийн модуль") -> 6 | D37: =COUNTIFS('Мобайл апп'!$B$5:$B$86,"4. Эмчийн модуль",'Мобайл апп'!$I$5:$I$86,"Дууссан") -> 0 | E37: =IFERROR(SUMIF('Мобайл апп'!$B$5:$B$86,"4. Эмчийн модуль",'Мобайл апп'!$J$5:$J$86)/COUNTIF('Мобайл апп'!$B$5:$B$86,"4. Эмчийн модуль"),0) -> 0 | F37: 08-06 – 08-23
B38: 5. Үйлчлүүлэгчийн модуль | C38: =COUNTIF('Мобайл апп'!$B$5:$B$86,"5. Үйлчлүүлэгчийн модуль") -> 8 | D38: =COUNTIFS('Мобайл апп'!$B$5:$B$86,"5. Үйлчлүүлэгчийн модуль",'Мобайл апп'!$I$5:$I$86,"Дууссан") -> 0 | E38: =IFERROR(SUMIF('Мобайл апп'!$B$5:$B$86,"5. Үйлчлүүлэгчийн модуль",'Мобайл апп'!$J$5:$J$86)/COUNTIF('Мобайл апп'!$B$5:$B$86,"5. Үйлчлүүлэгчийн модуль"),0) -> 0 | F38: 08-11 – 08-29
B39: 6. Нэмэлт модулиуд | C39: =COUNTIF('Мобайл апп'!$B$5:$B$86,"6. Нэмэлт модулиуд") -> 15 | D39: =COUNTIFS('Мобайл апп'!$B$5:$B$86,"6. Нэмэлт модулиуд",'Мобайл апп'!$I$5:$I$86,"Дууссан") -> 0 | E39: =IFERROR(SUMIF('Мобайл апп'!$B$5:$B$86,"6. Нэмэлт модулиуд",'Мобайл апп'!$J$5:$J$86)/COUNTIF('Мобайл апп'!$B$5:$B$86,"6. Нэмэлт модулиуд"),0) -> 0 | F39: 08-11 – 09-12
B40: 7. Админ болон тайлан | C40: =COUNTIF('Мобайл апп'!$B$5:$B$86,"7. Админ болон тайлан") -> 8 | D40: =COUNTIFS('Мобайл апп'!$B$5:$B$86,"7. Админ болон тайлан",'Мобайл апп'!$I$5:$I$86,"Дууссан") -> 0 | E40: =IFERROR(SUMIF('Мобайл апп'!$B$5:$B$86,"7. Админ болон тайлан",'Мобайл апп'!$J$5:$J$86)/COUNTIF('Мобайл апп'!$B$5:$B$86,"7. Админ болон тайлан"),0) -> 0 | F40: 08-26 – 09-10
B41: 8. Туршилт, аюулгүй байдал | C41: =COUNTIF('Мобайл апп'!$B$5:$B$86,"8. Туршилт, аюулгүй байдал") -> 6 | D41: =COUNTIFS('Мобайл апп'!$B$5:$B$86,"8. Туршилт, аюулгүй байдал",'Мобайл апп'!$I$5:$I$86,"Дууссан") -> 0 | E41: =IFERROR(SUMIF('Мобайл апп'!$B$5:$B$86,"8. Туршилт, аюулгүй байдал",'Мобайл апп'!$J$5:$J$86)/COUNTIF('Мобайл апп'!$B$5:$B$86,"8. Туршилт, аюулгүй байдал"),0) -> 0 | F41: 09-08 – 09-23
B42: 9. Нэвтрүүлэлт | C42: =COUNTIF('Мобайл апп'!$B$5:$B$86,"9. Нэвтрүүлэлт") -> 5 | D42: =COUNTIFS('Мобайл апп'!$B$5:$B$86,"9. Нэвтрүүлэлт",'Мобайл апп'!$I$5:$I$86,"Дууссан") -> 0 | E42: =IFERROR(SUMIF('Мобайл апп'!$B$5:$B$86,"9. Нэвтрүүлэлт",'Мобайл апп'!$J$5:$J$86)/COUNTIF('Мобайл апп'!$B$5:$B$86,"9. Нэвтрүүлэлт"),0) -> 0 | F42: 09-24 – 10-10
B43: 10. Баримт бичиг, сургалт | C43: =COUNTIF('Мобайл апп'!$B$5:$B$86,"10. Баримт бичиг, сургалт") -> 7 | D43: =COUNTIFS('Мобайл апп'!$B$5:$B$86,"10. Баримт бичиг, сургалт",'Мобайл апп'!$I$5:$I$86,"Дууссан") -> 0 | E43: =IFERROR(SUMIF('Мобайл апп'!$B$5:$B$86,"10. Баримт бичиг, сургалт",'Мобайл апп'!$J$5:$J$86)/COUNTIF('Мобайл апп'!$B$5:$B$86,"10. Баримт бичиг, сургалт"),0) -> 0 | F43: 10-10 – 10-15

Sheet Веб систем
A4: № | B4: Үе шат | C4: Модуль / Бүлэг | D4: Ажлын нэр | E4: Дэд ажил / Тодорхойлолт | F4: Хариуцагч тал | G4: Эхлэх огноо | H4: Дуусах огноо | I4: Төлөв | J4: Гүйцэтгэл % | K4: Хүлээн авах шалгуур | L4: Тэмдэглэл
A5: 1 | B5: 1. Шаардлагын судалгаа, шинжилгээ | C5: Судалгаа, шинжилгээ | D5: Ажлын хэсэг байгуулах | E5: Захиалагчийн талаас эмнэлзүйн ажлын хэсэг, холбоо барих хүмүүсийг томилох | F5: ЗСҮТ | G5: 46156 | H5: 46158 | I5: Дууссан | J5: 1 | K5: Ажлын хэсгийн бүрэлдэхүүн, хариуцах эмч нар тушаалаар батлагдсан
A6: 2 | B6: 1. Шаардлагын судалгаа, шинжилгээ | C6: Судалгаа, шинжилгээ | D6: Одоогийн системийн аудит | E6: МнКардио системийн эх код, өгөгдлийн сан, архитектурын одоогийн байдлыг судлах | F6: ITsystem | G6: 46156 | H6: 46162 | I6: Дууссан | J6: 1 | K6: Одоогийн систем, DB-ийн бүтцийн тайлан гарсан
A7: 3 | B7: 1. Шаардлагын судалгаа, шинжилгээ | C7: Судалгаа, шинжилгээ | D7: Маягтын эх сурвалж цуглуулах | E7: 14 маягтын батлагдсан цаасан хувилбар, бөглөх журам, заавар гаргаж өгөх | F7: ЗСҮТ | G7: 46156 | H7: 46162 | I7: Дууссан | J7: 1 | K7: Маягт бүрийн эцсийн хувилбар хүлээлгэн өгсөн | L7: 2026-09-09: Батлагдсан цаасан маягт хүлээгдэж байна — 12 маягтын хэвлэх хувилбарын хүлээн авалт хаагдаж байна (захидлын 2-р зүйл).
A8: 4 | B8: 1. Шаардлагын судалгаа, шинжилгээ | C8: Судалгаа, шинжилгээ | D8: Маягтын талбарын шинжилгээ | E8: Маягт бүрийн талбар, төрөл, сонголтын жагсаалт, давхардлыг шинжлэх | F8: ITsystem | G8: 46160 | H8: 46167 | I8: Дууссан | J8: 1 | K8: Талбарын шинжилгээний хүснэгт бэлэн
A9: 5 | B9: 1. Шаардлагын судалгаа, шинжилгээ | C9: Судалгаа, шинжилгээ | D9: Интеграцын судалгаа | E9: ХУР, ЭМД, ЭМХТ, Эмийн жор, ДАН, дүрс оношилгоо (PACS), лаборатори (LIS)-ийн сервисийн судалгаа | F9: ITsystem | G9: 46160 | H9: 46167 | I9: Дууссан | J9: 1 | K9: Сервис тус бүрийн техникийн боломж, шаардлагын тайлан
A10: 6 | B10: 1. Шаардлагын судалгаа, шинжилгээ | C10: Судалгаа, шинжилгээ | D10: А611 маягтын уялдаа | E10: ЭМХТ-ийн нэгдсэн системийн A611 маягттай уялдах шаардлагыг тодорхойлох | F10: ITsystem | G10: 46162 | H10: 46169 | I10: Дууссан | J10: 1 | K10: A611 талбарын харгалзаа (mapping) тодорхойлогдсон
A11: 7 | B11: 1. Шаардлагын судалгаа, шинжилгээ | C11: Судалгаа, шинжилгээ | D11: Хэрэглэгчийн эрхийн матриц | E11: Эмч, сувилагч, админ, иргэн зэрэг үүрэг тус бүрийн хандах эрхийг тодорхойлох | F11: ЗСҮТ | G11: 46162 | H11: 46169 | I11: Дууссан | J11: 1 | K11: Эрхийн матриц батлагдсан | L11: 2026-09-09: Захиалагчийн хариу хүлээж байна — ЗСҮТ-д хүргүүлсэн захидлын 8-р зүйл.
A12: 8 | B12: 1. Шаардлагын судалгаа, шинжилгээ | C12: Судалгаа, шинжилгээ | D12: Шаардлагын тодорхойлолт (SRS) | E12: Функционал болон функционал бус шаардлагын баримт бичиг боловсруулах | F12: ITsystem | G12: 46164 | H12: 46169 | I12: Дууссан | J12: 1 | K12: SRS баримт бичиг бүрэн боловсруулагдсан
A13: 9 | B13: 1. Шаардлагын судалгаа, шинжилгээ | C13: Судалгаа, шинжилгээ | D13: SRS батлах | E13: Шаардлагын баримт бичгийг хянаж, санал өгч, албан ёсоор батлах | F13: ЗСҮТ | G13: 46167 | H13: 46169 | I13: Дууссан | J13: 1 | K13: Захиалагчийн гарын үсэгтэй батлагдсан SRS | L13: 2026-09-09: Захиалагчийн хариу хүлээж байна — ЗСҮТ-д хүргүүлсэн захидлын 13-р зүйл.
A14: 10 | B14: 2. Архитектур, дизайн боловсруулах | C14: Архитектур, дизайн | D14: Системийн архитектур | E14: React JS / Node JS / Express JS / MSSQL-д суурилсан архитектурын дизайн боловсруулах | F14: ITsystem | G14: 46170 | H14: 46176 | I14: Дууссан | J14: 1 | K14: Архитектурын баримт бичиг бэлэн
A15: 11 | B15: 2. Архитектур, дизайн боловсруулах | C15: Архитектур, дизайн | D15: Аюулгүй байдлын загвар | E15: Эрхийн удирдлага, нууцлал, аудит лог, шифрлэлтийн шийдлийг төлөвлөх | F15: ITsystem | G15: 46170 | H15: 46176 | I15: Дууссан | J15: 1 | K15: Аюулгүй байдлын төлөвлөгөө батлагдсан
A16: 12 | B16: 2. Архитектур, дизайн боловсруулах | C16: Архитектур, дизайн | D16: Интеграцын архитектур | E16: Гадаад сервисүүдтэй холбогдох API давхарга, алдаа боловсруулалтын загвар | F16: ITsystem | G16: 46171 | H16: 46177 | I16: Дууссан | J16: 1 | K16: Интеграцын архитектурын схем бэлэн
A17: 13 | B17: 2. Архитектур, дизайн боловсруулах | C17: Архитектур, дизайн | D17: UI/UX дизайн | E17: Маягтын ерөнхий загвар, цэсний бүтэц, өнгө, товчлуурын стандарт боловсруулах | F17: ITsystem | G17: 46170 | H17: 46178 | I17: Дууссан | J17: 1 | K17: UI kit болон гол дэлгэцүүдийн дизайн бэлэн
J18: 1
J19: 1
A20: 16 | B20: 3. Өгөгдлийн сангийн загвар, маягтын бүтэц | C20: Өгөгдлийн сан, маягтын бүтэц | D20: DB ерөнхий схем | E20: MSSQL өгөгдлийн сангийн ерөнхий схемийг шинэ модулиудад тохируулан өргөтгөх | F20: ITsystem | G20: 46180 | H20: 46193 | I20: Дууссан | J20: 1 | K20: ER диаграм, хүснэгтийн жагсаалт бэлэн
A21: 17 | B21: 3. Өгөгдлийн сангийн загвар, маягтын бүтэц | C21: Өгөгдлийн сан, маягтын бүтэц | D21: Лавлах сан бүрдүүлэх | E21: ICD, эм, эмнэлгийн хэрэгсэл, ангилал, кодчиллын лавлах хүснэгтүүд | F21: ITsystem | G21: 46183 | H21: 46198 | I21: Дууссан | J21: 1 | K21: Лавлах хүснэгтүүд ачаалагдсан
A22: 18 | B22: 3. Өгөгдлийн сангийн загвар, маягтын бүтэц | C22: Өгөгдлийн сан, маягтын бүтэц | D22: Талбарын толь (Data dictionary) | E22: 14 маягтын нийт талбарын нэр, төрөл, урт, сонголт, заавал бөглөх эсэхийг нэгтгэх | F22: ITsystem | G22: 46183 | H22: 46203 | I22: Дууссан | J22: 1 | K22: Data dictionary баримт бүрэн
A23: 19 | B23: 3. Өгөгдлийн сангийн загвар, маягтын бүтэц | C23: Өгөгдлийн сан, маягтын бүтэц | D23: Талбарын толь батлах | E23: Маягтын бүтэц, талбарын толийг эмнэлзүйн баг хянаж батлах | F23: ЗСҮТ | G23: 46198 | H23: 46209 | I23: Саатсан | J23: 0 | K23: Захиалагч батласан талбарын толь | L23: 2026-09-09: 11 маягтын 1,687 талбарын эмнэлзүйн баталгаажуулалт хүлээгдэж байна (захидлын 3-р зүйл). | 2026-09-10: Төлөв залруулав — энэ мөр захиалагчаас хүлээгдэж байгаа тул «Дууссан» биш «Саатсан» байх ёстой (гүйцэтгэл 0%). Ажлын агуулга, хугацаа өөрчлөгдөөгүй. | 2026-09-10: Хуучин бүртгэлийн маягтуудын (AtrialRhythmNew, ICDRhythm, PaceMakerRhythm) тодорхойлолтод нэр (Label) дутуу 259 талбар илэрсэн тул баталгаажуулах хүснэгт бэлтгэв: «МнКардио_талбарын_нэр_баталгаажуулалт.xlsx». 156 талбарт кодоос санал гаргасан, 103-д нэр шинээр бичих шаардлагатай, 93 нь аль ч маягтад зурагддаггүй тул устгах эсэхийг шийдэх. Эдгээр талбар одоогоор хэвлэх, экспорт, мобайл API-д нэргүй тул гарахгүй байна. | 2026-09-11: Нэмэлт тодруулах 12 асуудлыг ZSUT-followup-2026-09-11.md-д жагсаав (шошго дахь хөгжүүлэгчийн заавар, 3.1-ийн заавал талбар, HAS-BLED, MoCA хавсралт г.м.).
A24: 20 | B24: 3. Өгөгдлийн сангийн загвар, маягтын бүтэц | C24: Өгөгдлийн сан, маягтын бүтэц | D24: Динамик маягтын модуль | E24: Маягтыг тохиргоогоор үүсгэх, засах боломжтой суурь модулийн бүтэц | F24: ITsystem | G24: 46188 | H24: 46209 | I24: Дууссан | J24: 1 | K24: Динамик маягтын модуль ажиллаж байна
A25: 21 | B25: 3. Өгөгдлийн сангийн загвар, маягтын бүтэц | C25: Өгөгдлийн сан, маягтын бүтэц | D25: Хөгжүүлэлтийн орчин | E25: Ubuntu 22.04 LTS, MSSQL 2017 Express+ дээр хөгжүүлэлт, туршилтын орчин бэлтгэх | F25: ITsystem | G25: 46180 | H25: 46188 | I25: Дууссан | J25: 1 | K25: Dev болон Test орчин ажиллагаанд орсон
A26: 22 | B26: 3. Өгөгдлийн сангийн загвар, маягтын бүтэц | C26: Өгөгдлийн сан, маягтын бүтэц | D26: Серверийн нөөц гаргах | E26: Туршилт болон үйлдвэрлэлийн серверийн техник хангамж, хандалтын эрх гаргаж өгөх | F26: ЗСҮТ | G26: 46180 | H26: 46193 | I26: Дууссан | J26: 0 | K26: Сервер, хандалтын эрх хүлээлгэн өгсөн | L26: 2026-09-09: Захиалагчийн хариу хүлээж байна — ЗСҮТ-д хүргүүлсэн захидлын 14-р зүйл. | 2026-09-10: Төлөв залруулав — энэ мөр захиалагчаас хүлээгдэж байгаа тул «Дууссан» биш «Саатсан» байх ёстой (гүйцэтгэл 0%). Ажлын агуулга, хугацаа өөрчлөгдөөгүй.
A27: 23 | B27: 4. Цахим маягт, модуль хөгжүүлэлт | C27: 1. Мэс заслын маягтууд | D27: 1.1 Мэс заслын өмнөх шалгуур хуудас (зүрхний нээлттэй мэс засал) | E27: Маягтын талбар, кодчилол, бөглөх дүрмийг эцэслэн батлах | F27: ЗСҮТ | G27: 46210 | H27: 46214 | I27: Дууссан | J27: 0 | K27: Талбар бүрийн нэр, төрөл, сонголтын жагсаалт, заавал бөглөх эсэх батлагдсан | L27: 2026-09-09: Талбарын толь, кодчилол, бөглөх дүрмийн баталгаажуулалт хүлээгдэж байна (захидлын 2, 3-р зүйл). | 2026-09-10: Төлөв залруулав — энэ мөр захиалагчаас хүлээгдэж байгаа тул «Дууссан» биш «Саатсан» байх ёстой (гүйцэтгэл 0%). Ажлын агуулга, хугацаа өөрчлөгдөөгүй.
A28: 24 | B28: 4. Цахим маягт, модуль хөгжүүлэлт | C28: 1. Мэс заслын маягтууд | D28: 1.1 Мэс заслын өмнөх шалгуур хуудас (зүрхний нээлттэй мэс засал) | E28: Өгөгдлийн сангийн хүснэгт, холбоос үүсгэх | F28: ITsystem | G28: 46212 | H28: 46216 | I28: Дууссан | J28: 1 | K28: Хүснэгт, индекс, гадаад түлхүүр үүссэн, тест дата орсон
A29: 25 | B29: 4. Цахим маягт, модуль хөгжүүлэлт | C29: 1. Мэс заслын маягтууд | D29: 1.1 Мэс заслын өмнөх шалгуур хуудас (зүрхний нээлттэй мэс засал) | E29: Маягтын дэлгэц (UI), CRUD, валидац хөгжүүлэх | F29: ITsystem | G29: 46215 | H29: 46221 | I29: Дууссан | J29: 1 | K29: Маягтыг нэмэх, засах, устгах, хадгалах бүрэн ажиллана; заавал талбарын шалгалт хийгдэнэ | L29: 2026-09-11: Маягтын хөдөлгүүрийн засвар: баталгаажсан бүртгэлийг сервер талд хэн ч засах, устгах боломжгүй (тендер 3.1 L8599-8605); өөр байгууллагын бүртгэлийг засах/баталгаажуулах/устгахыг хориглосон (админаас бусад); «Дуусгаж хадгалах» товч; баталгаажуулахад заавал талбарыг сервер шалгана; тоо/огнооны утгыг шалгана; нөхцөлт талбарын дүрэм (a|b, !x, дамжих) дэлгэц, хэвлэлт хоёрт нэг. backend 241393b, frontend 007266b; туршилтын орчинд байршуулсан. Шалгалт: API 20/20, хөтөч 20/20.
A30: 26 | B30: 4. Цахим маягт, модуль хөгжүүлэлт | C30: 1. Мэс заслын маягтууд | D30: 1.1 Мэс заслын өмнөх шалгуур хуудас (зүрхний нээлттэй мэс засал) | E30: Жагсаалт, хайлт, шүүлт, Excel экспорт | F30: ITsystem | G30: 46218 | H30: 46223 | I30: Дууссан | J30: 1 | K30: Цэсэнд жагсаалтаар харагдана; олон талбараар хайх, шүүх, .xlsx-ээр татах боломжтой
A31: 27 | B31: 4. Цахим маягт, модуль хөгжүүлэлт | C31: 1. Мэс заслын маягтууд | D31: 1.1 Мэс заслын өмнөх шалгуур хуудас (зүрхний нээлттэй мэс засал) | E31: Хэвлэх маягт (A4 / PDF) боловсруулах | F31: ITsystem | G31: 46220 | H31: 46224 | I31: Дууссан | J31: 1 | K31: Батлагдсан цаасан маягттай ижил бүтэцтэй хэвлэгдэнэ | L31: 2026-09-10: A4/PDF хэвлэлт сервер тал дээр нэгдсэн үүсгэгчээр бэлэн боллоо (reports/TenderForm.js, POST /TenderForm/PrintHtml ба /TenderForm/PrintReport). Маягтын толь бичгээр удирдагддаг тул шинэ маягт нэмэхэд хэвлэлт нэмэлт кодгүйгээр ажиллана. Хоосон болон бөглөсөн хувилбартай, нөхцөлт талбарыг нуух, шалгах хуудсыг Тийм/Үгүй/Тодорхойгүй нүдэн хүснэгтээр, титэм судасны 19 сегментийг нэг хүснэгтээр хэвлэнэ. Хуудасны дугаар ба эх сурвалжийн тэмдэглэгээ (байгууллага, мэдээллийн сан, огноо) хуудасны захад гарна. Батлагдсан цаасан маягттай эцсийн тулгалт ЗСҮТ-өөс эх хувь ирсний дараа (мөр 3).
A32: 28 | B32: 4. Цахим маягт, модуль хөгжүүлэлт | C32: 1. Мэс заслын маягтууд | D32: 1.1 Мэс заслын өмнөх шалгуур хуудас (зүрхний нээлттэй мэс засал) | E32: Захиалагчийн туршилт, баталгаажуулалт (UAT) | F32: ЗСҮТ | G32: 46223 | H32: 46227 | I32: Эхлээгүй | J32: 0 | K32: Эмч нар бодит өгөгдлөөр туршиж, санал/алдааны жагсаалт өгсөн
A33: 29 | B33: 4. Цахим маягт, модуль хөгжүүлэлт | C33: 1. Мэс заслын маягтууд | D33: 1.2 Мэс заслын үеийн шалгуур хуудас (аюулгүй байдлын хяналт) | E33: Маягтын талбар, кодчилол, бөглөх дүрмийг эцэслэн батлах | F33: ЗСҮТ | G33: 46210 | H33: 46214 | I33: Саатсан | J33: 0 | K33: Талбар бүрийн нэр, төрөл, сонголтын жагсаалт, заавал бөглөх эсэх батлагдсан | L33: 2026-09-09: Талбарын толь, кодчилол, бөглөх дүрмийн баталгаажуулалт хүлээгдэж байна (захидлын 2, 3-р зүйл). | 2026-09-10: Төлөв залруулав — энэ мөр захиалагчаас хүлээгдэж байгаа тул «Дууссан» биш «Саатсан» байх ёстой (гүйцэтгэл 0%). Ажлын агуулга, хугацаа өөрчлөгдөөгүй.
A34: 30 | B34: 4. Цахим маягт, модуль хөгжүүлэлт | C34: 1. Мэс заслын маягтууд | D34: 1.2 Мэс заслын үеийн шалгуур хуудас (аюулгүй байдлын хяналт) | E34: Өгөгдлийн сангийн хүснэгт, холбоос үүсгэх | F34: ITsystem | G34: 46212 | H34: 46216 | I34: Дууссан | J34: 1 | K34: Хүснэгт, индекс, гадаад түлхүүр үүссэн, тест дата орсон
A35: 31 | B35: 4. Цахим маягт, модуль хөгжүүлэлт | C35: 1. Мэс заслын маягтууд | D35: 1.2 Мэс заслын үеийн шалгуур хуудас (аюулгүй байдлын хяналт) | E35: Маягтын дэлгэц (UI), CRUD, валидац хөгжүүлэх | F35: ITsystem | G35: 46215 | H35: 46221 | I35: Дууссан | J35: 1 | K35: Маягтыг нэмэх, засах, устгах, хадгалах бүрэн ажиллана; заавал талбарын шалгалт хийгдэнэ | L35: 2026-09-11: Маягтын хөдөлгүүрийн засвар: баталгаажсан бүртгэлийг сервер талд хэн ч засах, устгах боломжгүй (тендер 3.1 L8599-8605); өөр байгууллагын бүртгэлийг засах/баталгаажуулах/устгахыг хориглосон (админаас бусад); «Дуусгаж хадгалах» товч; баталгаажуулахад заавал талбарыг сервер шалгана; тоо/огнооны утгыг шалгана; нөхцөлт талбарын дүрэм (a|b, !x, дамжих) дэлгэц, хэвлэлт хоёрт нэг. backend 241393b, frontend 007266b; туршилтын орчинд байршуулсан. Шалгалт: API 20/20, хөтөч 20/20.
A36: 32 | B36: 4. Цахим маягт, модуль хөгжүүлэлт | C36: 1. Мэс заслын маягтууд | D36: 1.2 Мэс заслын үеийн шалгуур хуудас (аюулгүй байдлын хяналт) | E36: Жагсаалт, хайлт, шүүлт, Excel экспорт | F36: ITsystem | G36: 46218 | H36: 46223 | I36: Дууссан | J36: 1 | K36: Цэсэнд жагсаалтаар харагдана; олон талбараар хайх, шүүх, .xlsx-ээр татах боломжтой
A37: 33 | B37: 4. Цахим маягт, модуль хөгжүүлэлт | C37: 1. Мэс заслын маягтууд | D37: 1.2 Мэс заслын үеийн шалгуур хуудас (аюулгүй байдлын хяналт) | E37: Хэвлэх маягт (A4 / PDF) боловсруулах | F37: ITsystem | G37: 46220 | H37: 46224 | I37: Дууссан | J37: 1 | K37: Батлагдсан цаасан маягттай ижил бүтэцтэй хэвлэгдэнэ | L37: 2026-09-09: Маягт 1.2-ын агуулгыг тендерийн зурган хавсралтаас бүрэн буулгаж 75 талбараар ачаалав (scripts/seed_form_1_2.sql). A4 хэвлэлт TenderFormPrint.jsx-ээр ажиллана. Толь бичгийн эмнэлзүйн баталгаажуулалт үлдсэн. | 2026-09-10: A4/PDF хэвлэлт сервер тал дээр нэгдсэн үүсгэгчээр бэлэн боллоо (reports/TenderForm.js, POST /TenderForm/PrintHtml ба /TenderForm/PrintReport). Маягтын толь бичгээр удирдагддаг тул шинэ маягт нэмэхэд хэвлэлт нэмэлт кодгүйгээр ажиллана. Хоосон болон бөглөсөн хувилбартай, нөхцөлт талбарыг нуух, шалгах хуудсыг Тийм/Үгүй/Тодорхойгүй нүдэн хүснэгтээр, титэм судасны 19 сегментийг нэг хүснэгтээр хэвлэнэ. Хуудасны дугаар ба эх сурвалжийн тэмдэглэгээ (байгууллага, мэдээллийн сан, огноо) хуудасны захад гарна. Батлагдсан цаасан маягттай эцсийн тулгалт ЗСҮТ-өөс эх хувь ирсний дараа (мөр 3).
A38: 34 | B38: 4. Цахим маягт, модуль хөгжүүлэлт | C38: 1. Мэс заслын маягтууд | D38: 1.2 Мэс заслын үеийн шалгуур хуудас (аюулгүй байдлын хяналт) | E38: Захиалагчийн туршилт, баталгаажуулалт (UAT) | F38: ЗСҮТ | G38: 46223 | H38: 46227 | I38: Эхлээгүй | J38: 0 | K38: Эмч нар бодит өгөгдлөөр туршиж, санал/алдааны жагсаалт өгсөн
A39: 35 | B39: 4. Цахим маягт, модуль хөгжүүлэлт | C39: 1. Мэс заслын маягтууд | D39: 1.3 Хэвлийн гол судасны цүлхэн, гол судас-ташааны артерийн мэс заслын өмнөх шалгах хуудас | E39: Маягтын талбар, кодчилол, бөглөх дүрмийг эцэслэн батлах | F39: ЗСҮТ | G39: 46216 | H39: 46220 | I39: Саатсан | J39: 0 | K39: Талбар бүрийн нэр, төрөл, сонголтын жагсаалт, заавал бөглөх эсэх батлагдсан | L39: 2026-09-09: Талбарын толь, кодчилол, бөглөх дүрмийн баталгаажуулалт хүлээгдэж байна (захидлын 2, 3-р зүйл). | 2026-09-10: Төлөв залруулав — энэ мөр захиалагчаас хүлээгдэж байгаа тул «Дууссан» биш «Саатсан» байх ёстой (гүйцэтгэл 0%). Ажлын агуулга, хугацаа өөрчлөгдөөгүй.
A40: 36 | B40: 4. Цахим маягт, модуль хөгжүүлэлт | C40: 1. Мэс заслын маягтууд | D40: 1.3 Хэвлийн гол судасны цүлхэн, гол судас-ташааны артерийн мэс заслын өмнөх шалгах хуудас | E40: Өгөгдлийн сангийн хүснэгт, холбоос үүсгэх | F40: ITsystem | G40: 46218 | H40: 46222 | I40: Дууссан | J40: 1 | K40: Хүснэгт, индекс, гадаад түлхүүр үүссэн, тест дата орсон
A41: 37 | B41: 4. Цахим маягт, модуль хөгжүүлэлт | C41: 1. Мэс заслын маягтууд | D41: 1.3 Хэвлийн гол судасны цүлхэн, гол судас-ташааны артерийн мэс заслын өмнөх шалгах хуудас | E41: Маягтын дэлгэц (UI), CRUD, валидац хөгжүүлэх | F41: ITsystem | G41: 46221 | H41: 46228 | I41: Дууссан | J41: 1 | K41: Маягтыг нэмэх, засах, устгах, хадгалах бүрэн ажиллана; заавал талбарын шалгалт хийгдэнэ | L41: 2026-09-11: Маягтын хөдөлгүүрийн засвар: баталгаажсан бүртгэлийг сервер талд хэн ч засах, устгах боломжгүй (тендер 3.1 L8599-8605); өөр байгууллагын бүртгэлийг засах/баталгаажуулах/устгахыг хориглосон (админаас бусад); «Дуусгаж хадгалах» товч; баталгаажуулахад заавал талбарыг сервер шалгана; тоо/огнооны утгыг шалгана; нөхцөлт талбарын дүрэм (a|b, !x, дамжих) дэлгэц, хэвлэлт хоёрт нэг. backend 241393b, frontend 007266b; туршилтын орчинд байршуулсан. Шалгалт: API 20/20, хөтөч 20/20.
A42: 38 | B42: 4. Цахим маягт, модуль хөгжүүлэлт | C42: 1. Мэс заслын маягтууд | D42: 1.3 Хэвлийн гол судасны цүлхэн, гол судас-ташааны артерийн мэс заслын өмнөх шалгах хуудас | E42: Жагсаалт, хайлт, шүүлт, Excel экспорт | F42: ITsystem | G42: 46225 | H42: 46230 | I42: Дууссан | J42: 1 | K42: Цэсэнд жагсаалтаар харагдана; олон талбараар хайх, шүүх, .xlsx-ээр татах боломжтой
A43: 39 | B43: 4. Цахим маягт, модуль хөгжүүлэлт | C43: 1. Мэс заслын маягтууд | D43: 1.3 Хэвлийн гол судасны цүлхэн, гол судас-ташааны артерийн мэс заслын өмнөх шалгах хуудас | E43: Хэвлэх маягт (A4 / PDF) боловсруулах | F43: ITsystem | G43: 46227 | H43: 46231 | I43: Дууссан | J43: 0.5 | K43: Батлагдсан цаасан маягттай ижил бүтэцтэй хэвлэгдэнэ | L43: 2026-09-10: A4/PDF хэвлэлт сервер тал дээр нэгдсэн үүсгэгчээр бэлэн боллоо (reports/TenderForm.js, POST /TenderForm/PrintHtml ба /TenderForm/PrintReport). Маягтын толь бичгээр удирдагддаг тул шинэ маягт нэмэхэд хэвлэлт нэмэлт кодгүйгээр ажиллана. Хоосон болон бөглөсөн хувилбартай, нөхцөлт талбарыг нуух, шалгах хуудсыг Тийм/Үгүй/Тодорхойгүй нүдэн хүснэгтээр, титэм судасны 19 сегментийг нэг хүснэгтээр хэвлэнэ. Хуудасны дугаар ба эх сурвалжийн тэмдэглэгээ (байгууллага, мэдээллийн сан, огноо) хуудасны захад гарна. Батлагдсан цаасан маягттай эцсийн тулгалт ЗСҮТ-өөс эх хувь ирсний дараа (мөр 3).
...

Sheet Мобайл апп
A1: МОБАЙЛ АПП
A4: № | B4: Үе шат | C4: Модуль / Бүлэг | D4: Ажлын нэр | E4: Дэд ажил / Тодорхойлолт | F4: Хариуцагч тал | G4: Эхлэх огноо | H4: Дуусах огноо | I4: Төлөв | J4: Гүйцэтгэл % | K4: Хүлээн авах шалгуур | L4: Тэмдэглэл
A5: 1 | B5: 1. Шинжилгээ, төлөвлөлт | C5: Шинжилгээ, төлөвлөлт | D5: Шаардлагын шинжилгээ, SRS | E5: Мобайл аппын функционал шаардлагыг задлан SRS боловсруулах | F5: ITsystem | G5: 46206 | H5: 46213 | I5: Дууссан | J5: 1 | K5: SRS баримт бэлэн | L5: 2026-09-09: Төлөв 'Дууссан' атлаа гүйцэтгэл 0% бичигдсэн байсныг 100% болгож залруулав.
A6: 2 | B6: 1. Шинжилгээ, төлөвлөлт | C6: Шинжилгээ, төлөвлөлт | D6: Backend API-ийн судалгаа | E6: МнКардио веб системийн API, өгөгдлийн сангийн боломжийг судлах | F6: ITsystem | G6: 46206 | H6: 46211 | I6: Дууссан | J6: 1 | K6: Ашиглах API-уудын жагсаалт, дутуу API тодорхойлогдсон | L6: 2026-09-09: Төлөв 'Дууссан' атлаа гүйцэтгэл 0% бичигдсэн байсныг 100% болгож залруулав.
A7: 3 | B7: 1. Шинжилгээ, төлөвлөлт | C7: Шинжилгээ, төлөвлөлт | D7: Өгөгдлийн сангийн судалгаа | E7: Мобайлд шаардагдах өгөгдөл, шинээр нэмэх хүснэгтийг тодорхойлох | F7: ITsystem | G7: 46209 | H7: 46213 | I7: Дууссан | J7: 1 | K7: Өгөгдлийн шаардлагын тайлан | L7: 2026-09-09: Төлөв 'Дууссан' атлаа гүйцэтгэл 0% бичигдсэн байсныг 100% болгож залруулав.
A8: 4 | B8: 1. Шинжилгээ, төлөвлөлт | C8: Шинжилгээ, төлөвлөлт | D8: Хэрэглээний шаардлага тодруулах | E8: Эмч болон үйлчлүүлэгчийн талын бодит хэрэглээ, хүлээлтийг тодруулах | F8: ЗСҮТ | G8: 46206 | H8: 46213 | I8: Саатсан | J8: 0 | K8: Хэрэглэгчийн ярилцлагын дүн, шаардлагын жагсаалт | L8: 2026-09-09: Захиалагчийн хариу хүлээж байна — ЗСҮТ-д хүргүүлсэн захидлын 13-р зүйл.
A9: 5 | B9: 1. Шинжилгээ, төлөвлөлт | C9: Шинжилгээ, төлөвлөлт | D9: Хөгжүүлэлтийн орчин бэлтгэх | E9: Android / iOS хөгжүүлэлт, туршилтын орчин, төхөөрөмж бэлтгэх | F9: ITsystem | G9: 46209 | H9: 46215 | I9: Дууссан | J9: 1 | K9: Dev, Test орчин бэлэн | L9: 2026-09-09: Төлөв 'Дууссан' атлаа гүйцэтгэл 0% бичигдсэн байсныг 100% болгож залруулав.
A10: 6 | B10: 1. Шинжилгээ, төлөвлөлт | C10: Шинжилгээ, төлөвлөлт | D10: SRS батлах | E10: Шаардлагын баримтыг хянаж батлах | F10: ЗСҮТ | G10: 46211 | H10: 46215 | I10: Дууссан | J10: 1 | K10: Батлагдсан SRS | L10: 2026-09-09: Төлөв 'Дууссан' атлаа гүйцэтгэл 0% бичигдсэн байсныг 100% болгож залруулав.
A11: 7 | B11: 2. Архитектур, UI/UX дизайн | C11: Архитектур, UI/UX | D11: Мобайл архитектур | E11: Android болон iOS дээр ажиллах архитектур, технологийн сонголт | F11: ITsystem | G11: 46213 | H11: 46219 | I11: Дууссан | J11: 1 | K11: Архитектурын баримт бэлэн | L11: 2026-09-09: Төлөв 'Дууссан' атлаа гүйцэтгэл 0% бичигдсэн байсныг 100% болгож залруулав.
A12: 8 | B12: 2. Архитектур, UI/UX дизайн | C12: Архитектур, UI/UX | D12: Өгөгдлийн сангийн загвар | E12: Мобайлд шаардагдах хүснэгт, локал кэшийн загвар | F12: ITsystem | G12: 46216 | H12: 46221 | I12: Дууссан | J12: 1 | K12: DB загвар батлагдсан | L12: 2026-09-09: Төлөв 'Дууссан' атлаа гүйцэтгэл 0% бичигдсэн байсныг 100% болгож залруулав.
A13: 9 | B13: 2. Архитектур, UI/UX дизайн | C13: Архитектур, UI/UX | D13: Аюулгүй байдлын төлөвлөлт | E13: Токен, шифрлэлт, төхөөрөмжийн аюулгүй байдлын шийдэл | F13: ITsystem | G13: 46216 | H13: 46221 | I13: Дууссан | J13: 1 | K13: Аюулгүй байдлын төлөвлөгөө бэлэн | L13: 2026-09-09: Төлөв 'Дууссан' атлаа гүйцэтгэл 0% бичигдсэн байсныг 100% болгож залруулав.
A14: 10 | B14: 2. Архитектур, UI/UX дизайн | C14: Архитектур, UI/UX | D14: UI/UX дизайн, прототип | E14: Эмч болон үйлчлүүлэгчийн бүх дэлгэцийн дизайн, прототип | F14: ITsystem | G14: 46216 | H14: 46225 | I14: Дууссан | J14: 1 | K14: Интерактив прототип бэлэн (монгол хэл дээр) | L14: 2026-09-09: Төлөв 'Дууссан' атлаа гүйцэтгэл 0% бичигдсэн байсныг 100% болгож залруулав.
A15: 11 | B15: 2. Архитектур, UI/UX дизайн | C15: Архитектур, UI/UX | D15: Прототипыг хянаж батлах | E15: Дизайныг эмч, үйлчлүүлэгчийн төлөөлөлд танилцуулж батлах | F15: ЗСҮТ | G15: 46223 | H15: 46227 | I15: Саатсан | J15: 0 | K15: Батлагдсан дизайн, саналын хуудас | L15: 2026-09-09: Захиалагчийн хариу хүлээж байна — ЗСҮТ-д хүргүүлсэн захидлын 12-р зүйл.
A16: 12 | B16: 3. Суурь систем хөгжүүлэлт | C16: Суурь систем | D16: Нэвтрэлт, эрхийн удирдлага | E16: Эмч / үйлчлүүлэгч гэсэн 2 төрлийн нэвтрэлт, хэрэглэгч тус бүрээр үйлдэл тохируулах | F16: ITsystem | G16: 46225 | H16: 46235 | I16: Дууссан | J16: 1 | K16: Хэрэглэгч бүрийн эрхийг админаас тохируулж болно | L16: 2026-09-09: Төлөв 'Дууссан' атлаа гүйцэтгэл 0% бичигдсэн байсныг 100% болгож залруулав.
... A19: 15 | B19: 3. Суурь систем хөгжүүлэлт | C19: Суурь систем | D19: Нууц үг сэргээх | E19: Админы дэмжлэггүйгээр нууц үгээ сэргээх урсгал | F19: ITsystem | G19: 46230 | H19: 46237 | I19: Хийгдэж байна | J19: 0.5 | K19: Хэрэглэгч өөрөө нууц үгээ сэргээнэ | L19: 2026-09-10: Сервер талын урсгал бэлэн — өөрөө нууц үгээ сэргээх хүсэлт, и-мэйлийн баталгаажуулалт (controllers/auth/UserRequestController.js, helper/MailHelper.js, commit c9cc41c). Гар утасны дэлгэц бичигдээгүй.
A20: 16 | B20: 3. Суурь систем хөгжүүлэлт | C20: Суурь систем | D20: Буруу нэвтрэлтийн мэдэгдэл | E20: Нууц үгээ 3 удаа буруу оруулсан үед мэдэгдэл илгээх | F20: ITsystem | G20: 46232 | H20: 46237 | I20: Эхлээгүй | J20: 0 | K20: 3 дахь оролдлогод мэдэгдэл хүрнэ
A21: 17 | B21: 3. Суурь систем хөгжүүлэлт | C21: Суурь систем | D21: ХУР интеграц | E21: Үйлчлүүлэгчийн бүртгэл үүсгэх, шинэчлэхэд ХУР-аас мэдээлэл татах | F21: ITsystem | G21: 46230 | H21: 46242 | I21: Саатсан | J21: 0 | K21: Регистрээр иргэний мэдээлэл татагдана
A22: 18 | B22: 3. Суурь систем хөгжүүлэлт | C22: Суурь систем | D22: ЭМД болон эмийн сангийн кодчилол | E22: Эрүүл мэндийн даатгал, эм эмнэлгийн хэрэгслийн нэгдсэн сангаас кодчилол татах | F22: ITsystem | G22: 46235 | H22: 46246 | I22: Саатсан | J22: 0 | K22: Лавлах мэдээлэл автоматаар шинэчлэгдэнэ
A23: 19 | B23: 3. Суурь систем хөгжүүлэлт | C23: Суурь систем | D23: Стандарт кодчилол нэвтрүүлэх | E23: ICD, FHIR/HL7, SNOMED CT, LOINC стандартыг дагаж мөрдөх | F23: ITsystem | G23: 46235 | H23: 46248 | I23: Эхлээгүй | J23: 0 | K23: Мэдээлэл солилцоо стандартын дагуу
A24: 20 | B24: 3. Суурь систем хөгжүүлэлт | C24: Суурь систем | D24: Эрүүл мэндийн салбарын мэдээлэл солилцоо | E24: Салбарын мэдээлэл солилцооны системтэй стандартын дагуу холбогдох | F24: ITsystem | G24: 46237 | H24: 46250 | I24: Эхлээгүй | J24: 0 | K24: Мэдээлэл нийлүүлэх, хүлээн авах ажиллагаа шалгагдсан
A25: 21 | B25: 3. Суурь систем хөгжүүлэлт | C25: Суурь систем | D25: Нууцлалын эрхийн тохиргоо | E25: Албаны нууцад хамаарах мэдээлэлд хандах эрхийг тусгайлан тохируулах | F25: ITsystem | G25: 46237 | H25: 46246 | I25: Эхлээгүй | J25: 0 | K25: Нууц ангиллын мэдээлэл эрхгүй хэрэглэгчид харагдахгүй
A26: 22 | B26: 3. Суурь систем хөгжүүлэлт | C26: Суурь систем | D26: Нууцлалын журам, эрхийн матриц | E26: Албаны нууцын ангилал, эрхийн матрицыг батлах | F26: ЗСҮТ | G26: 46225 | H26: 46237 | I26: Саатсан | J26: 0 | K26: Батлагдсан эрхийн матриц | L26: 2026-09-09: Захиалагчийн хариу хүлээж байна — ЗСҮТ-д хүргүүлсэн захидлын 8-р зүйл.
A27: 23 | B27: 3. Суурь систем хөгжүүлэлт | C27: Суурь систем | D27: Мэдээлэл ашиглах зөвшөөрөл | E27: Мэдээллийн эзэн / асран хамгаалагчаас зөвшөөрөл авах урсгал | F27: ITsystem | G27: 46239 | H27: 46248 | I27: Эхлээгүй | J27: 0 | K27: Зөвшөөрөл бүртгэгдэж, түүх хадгалагдана
A28: 24 | B28: 3. Суурь систем хөгжүүлэлт | C28: Суурь систем | D28: Хандалтын мэдэгдэл | E28: Үйлчлүүлэгчийн мэдээлэлд хандсан үед мэдэгдэл хүргэх | F28: ITsystem | G28: 46239 | H28: 46248 | I28: Саатсан | J28: 0 | K28: Хандалт бүрт мэдэгдэл очно | L28: 2026-09-09: Мэдэгдлийн хамрах хүрээг захиалагч сонгоно — хандалт бүрд / өдөрт нэг удаа / зөвхөн гадны хандалт (захидлын 15-р зүйл).
A29: 25 | B29: 3. Суурь систем хөгжүүлэлт | C29: Суурь систем | D29: Хайлтын систем | E29: Хугацааны интервал болон бүх төрлийн талбарын утгаар хайх | F29: ITsystem | G29: 46239 | H29: 46250 | I29: Эхлээгүй | J29: 0 | K29: Үйлчлүүлэгч, онош, эмч, огноогоор хайна
A30: 26 | B30: 3. Суурь систем хөгжүүлэлт | C30: Суурь систем | D30: Цахим гарын үсэг | E30: Цахим гарын үсгийг дэмжих | F30: ITsystem | G30: 46242 | H30: 46250 | I30: Эхлээгүй | J30: 0 | K30: Баримтыг цахим гарын үсгээр баталгаажуулна
A31: 27 | B31: 3. Суурь систем хөгжүүлэлт | C31: Суурь систем | D31: Нөөцлөлт, цагийн эталон | E31: Хууль журамд заасан хугацаагаар backup хийх, улсын цагийн эталон ашиглах | F31: ITsystem | G31: 46242 | H31: 46250 | I31: Эхлээгүй | J31: 0 | K31: Автомат backup, цагийн эх сурвалж тохируулагдсан
A32: 28 | B32: 4. Эмчийн модуль | C32: Эмчийн модуль | D32: Миний үзлэгүүд | E32: Эмчийн хийсэн үзлэгийн жагсаалт, дэлгэрэнгүй | F32: ITsystem | G32: 46240 | H32: 46248 | I32: Эхлээгүй | J32: 0 | K32: Үзлэгийн жагсаалт, хайлт ажиллана | L32: 2026-09-10: Энэ дэлгэцийг тэжээх сервер тал бэлэн — GET /api/doctor/visits, /api/doctor/visits/:id (веб жагсаалтын мөр #129). Гар утасны апп-ын код бичигдээгүй тул гүйцэтгэл 0 хэвээр.
A33: 29 | B33: 4. Эмчийн модуль | C33: Эмчийн модуль | D33: Миний хяналт | E33: Хяналтад авсан үйлчлүүлэгчдийн жагсаалт, хяналтын түүх | F33: ITsystem | G33: 46242 | H33: 46251 | I33: Эхлээгүй | J33: 0 | K33: Хяналтын мэдээлэл бүрэн харагдана | L33: 2026-09-10: Энэ дэлгэцийг тэжээх сервер тал бэлэн — GET|POST|DELETE /api/doctor/monitoring, /monitoring/:id/journal (веб жагсаалтын мөр #129). Гар утасны апп-ын код бичигдээгүй тул гүйцэтгэл 0 хэвээр.
A34: 30 | B34: 4. Эмчийн модуль | C34: Эмчийн модуль | D34: Миний зөвлөгөө | E34: Өгсөн зөвлөгөөний жагсаалт, шинээр зөвлөгөө өгөх | F34: ITsystem | G34: 46245 | H34: 46253 | I34: Эхлээгүй | J34: 0 | K34: Зөвлөгөө үүсгэх, харах боломжтой | L34: 2026-09-10: Энэ дэлгэцийг тэжээх сервер тал бэлэн — GET /api/doctor/advice, /api/doctor/advice/:id (веб жагсаалтын мөр #129). Гар утасны апп-ын код бичигдээгүй тул гүйцэтгэл 0 хэвээр.
A35: 31 | B35: 4. Эмчийн модуль | C35: Эмчийн модуль | D35: Миний тайлан | E35: Эмчийн үйл ажиллагааны тайлан, статистик | F35: ITsystem | G35: 46247 | H35: 46255 | I35: Эхлээгүй | J35: 0 | K35: Тайлан гарч, экспорт хийгдэнэ | L35: 2026-09-10: Энэ дэлгэцийг тэжээх сервер тал бэлэн — GET /api/doctor/reports/summary (веб жагсаалтын мөр #129). Гар утасны апп-ын код бичигдээгүй тул гүйцэтгэл 0 хэвээр.
A36: 32 | B36: 4. Эмчийн модуль | C36: Эмчийн модуль | D36: Үйлчлүүлэгчийн модуль харах | E36: Эмч нь эрсдэл, цахим үзлэг, сэргээн засахын мэдээллийг харах | F36: ITsystem | G36: 46248 | H36: 46257 | I36: Эхлээгүй | J36: 0 | K36: Эмч үйлчлүүлэгчийн модулийг унших эрхтэй харна | L36: 2026-09-10: Энэ дэлгэцийг тэжээх сервер тал бэлэн — GET /api/doctor/patients, /api/doctor/patients/:id (веб жагсаалтын мөр #129). Гар утасны апп-ын код бичигдээгүй тул гүйцэтгэл 0 хэвээр.
A37: 33 | B37: 4. Эмчийн модуль | C37: Эмчийн модуль | D37: Эмчийн модулийн туршилт | E37: Эмч нараар турших, санал авах | F37: ЗСҮТ | G37: 46253 | H37: 46257 | I37: Эхлээгүй | J37: 0 | K37: Туршилтын санал, алдааны жагсаалт
A38: 34 | B38: 5. Үйлчлүүлэгчийн модуль | C38: Үйлчлүүлэгчийн модуль | D38: 2.1 Миний бүртгэл | E38: Хувийн мэдээлэл, бүртгэл, ХУР-аас татсан өгөгдөл | F38: ITsystem | G38: 46245 | H38: 46252 | I38: Эхлээгүй | J38: 0 | K38: Бүртгэл үүсгэх, засах ажиллана | L38: 2026-09-10: Энэ дэлгэцийг тэжээх сервер тал бэлэн — GET /api/patient/me (веб жагсаалтын мөр #129). Гар утасны апп-ын код бичигдээгүй тул гүйцэтгэл 0 хэвээр.
A39: 35 | B39: 5. Үйлчлүүлэгчийн модуль | C39: Үйлчлүүлэгчийн модуль | D39: 2.2 Миний тэмдэглэл | E39: Өдөр тутмын эрүүл мэндийн бүртгэл (даралт, судас, жин, эм г.м.) | F39: ITsystem | G39: 46247 | H39: 46255 | I39: Эхлээгүй | J39: 0 | K39: Өдөр тутмын бүртгэл орж, график хэлбэрээр харагдана | L39: 2026-09-10: Энэ дэлгэцийг тэжээх сервер тал бэлэн — GET|POST /api/patient/journal, /journal/summary (веб жагсаалтын мөр #129). Гар утасны апп-ын код бичигдээгүй тул гүйцэтгэл 0 хэвээр.
A40: 36 | B40: 5. Үйлчлүүлэгчийн модуль | C40: Үйлчлүүлэгчийн модуль | D40: 2.3 Эмчээс асуух асуулт | E40: Үйлчлүүлэгч эмчид асуулт илгээх | F40: ITsystem | G40: 46248 | H40: 46256 | I40: Эхлээгүй | J40: 0 | K40: Асуулт илгээгдэж, эмчид хүрнэ | L40: 2026-09-10: Энэ дэлгэцийг тэжээх сервер тал бэлэн — GET|POST /api/patient/questions (веб жагсаалтын мөр #129). Гар утасны апп-ын код бичигдээгүй тул гүйцэтгэл 0 хэвээр.
A41: 37 | B41: 5. Үйлчлүүлэгчийн модуль | C41: Үйлчлүүлэгчийн модуль | D41: 2.4 Эмчийн зөвлөгөө | E41: Эмчээс ирсэн зөвлөгөөг харах | F41: ITsystem | G41: 46251 | H41: 46258 | I41: Эхлээгүй | J41: 0 | K41: Зөвлөгөө мэдэгдэлтэйгээр хүрнэ | L41: 2026-09-10: Энэ дэлгэцийг тэжээх сервер тал бэлэн — GET /api/patient/advice (веб жагсаалтын мөр #129). Гар утасны апп-ын код бичигдээгүй тул гүйцэтгэл 0 хэвээр.
A42: 38 | B42: 5. Үйлчлүүлэгчийн модуль | C42: Үйлчлүүлэгчийн модуль | D42: Эрсдэлийн аргачлал батлах | E42: ЗСӨ эрсдэлийн үнэлгээний асуумж, оноо, ангиллыг батлах | F42: ЗСҮТ | G42: 46245 | H42: 46252 | I42: Саатсан | J42: 0 | K42: Аргачлал батлагдсан | L42: 2026-09-09: Захиалагчийн хариу хүлээж байна — ЗСҮТ-д хүргүүлсэн захидлын 5-р зүйл.
A43: 39 | B43: 5. Үйлчлүүлэгчийн модуль | C43: Үйлчлүүлэгчийн модуль | D43: 2.5 Эрсдэлийн үнэлгээ (ЗСӨ) | E43: Үйлчлүүлэгч өөрөө эрсдэлээ үнэлэх модуль | F43: ITsystem | G43: 46251 | H43: 46260 | I43: Эхлээгүй | J43: 0 | K43: Асуумж бөглөж эрсдэлийн оноо, зөвлөмж гарна | L43: 2026-09-10: Энэ дэлгэцийг тэжээх сервер тал бэлэн — GET /api/patient/risk (веб жагсаалтын мөр #129). Гар утасны апп-ын код бичигдээгүй тул гүйцэтгэл 0 хэвээр.
A44: 40 | B44: 5. Үйлчлүүлэгчийн модуль | C44: Үйлчлүүлэгчийн модуль | D44: 2.6 Цахим үзлэг | E44: Алсын зайн үзлэгийн хүсэлт, цаг захиалга, үзлэг | F44: ITsystem | G44: 46252 | H44: 46262 | I44: Эхлээгүй | J44: 0 | K44: Цахим үзлэгийн бүрэн урсгал ажиллана | L44: 2026-09-10: Энэ дэлгэцийг тэжээх сервер тал бэлэн — GET|POST /api/patient/evisits (веб жагсаалтын мөр #129). Гар утасны апп-ын код бичигдээгүй тул гүйцэтгэл 0 хэвээр.
...

Sheet Веб — санал, тайлан 09-10
A1: ВЕБ СИСТЕМ — ГҮЙЦЭТГЭГЧИЙН САНАЛ, ТАЙЛАН
A2: Огноо: 2026-09-10 · Гүйцэтгэгч: ITsystem · Захиалагч: Зүрх судасны үндэсний төв (ЗСҮТ) · Гэрээний хугацаа: 2026-05-14 – 2026-09-14
A3: Туршилтын орчин: https://mncardio.itsystem.mn — доорх бүх дэлгэцийг энэ хаягаар өөрсдөө нээж үзэх боломжтой. «Дэлгэцийн зураг» багана дахь зургууд нь 2026-09-10-нд тус орчноос авсан бөгөөд энэ файлд шингээгдсэн болно.
A5: № | B5: Ангилал | C5: Сэдэв | D5: Одоогийн байдал / Тайлбар | E5: Хаанаас харах · Хэн хийх | F5: Холбогдох мөр | G5: Ач холбогдол | H5: Хугацаа | I5: Дэлгэцийн зураг
A6: А. ХИЙГДСЭН АЖИЛ — ГҮЙЦЭТГЭГЧ (ITsystem), 2026-09-10-ны байдлаар
A7: 1 | B7: Орчин | C7: Туршилтын орчин ажиллагаанд орлоо | D7: Веб систем ба мобайл апп хоёулаа энэ орчин дээр ажиллана. Мэдээллийн сан нь MnCardio_test — үйлдвэрлэлийн SQL серверт байрлах тусдаа сан, туршилтын хэрэглэгчийн эрх олгосон. nginx, TLS гэрчилгээ, PM2, логийн эргэлт (pm2-logrotate) тохируулсан. Захиалагчаас үйлдвэрлэлийн сервер хараахан гараагүй тул (мөр #22) гүйцэтгэгч өөрийн нөөц дээр түр байгуулав. | E7: https://mncardio.itsystem.mn | F7: #22, #146 | H7: 2026-09-10
A8: 2 | B8: UI / UX | C8: Нэвтрэх хуудас шинэчлэгдэв | D8: Монгол орон нутгийн зураглал дээр аймаг бүрийн зайн оношилгооны холбоос, зүрхний цахилгаан бичлэгийн долгион хөдөлнө. Хэрэглэгч бичиж эхлэхэд хөдөлгөөн бүдгэрч анхаарал сарниулахгүй, цонх нуугдахад бүрэн зогсоно. Хар дэвсгэр (dark mode) дэмжинэ. Нууц үг 3 удаа буруу оруулбал серверийн алдааг давтахаа болиод мэдээллийн технологийн ажилтны утсыг харуулна. | E8: https://mncardio.itsystem.mn/auth/login | H8: 2026-09-10
A9: 3 | B9: UI / UX | C9: Дэлгэц хооронд таб нээх боломж | D9: Нээсэн дэлгэц бүр таб болж үлдэнэ. Хагас бөглөсөн маягтаас өөр хүний мэдээлэл рүү орж, буцаж ирэхэд бөглөсөн зүйл хэвээр байна — өмнө нь дахин ачаалж, оруулсан өгөгдөл алга болдог байв. Хөтчийн Буцах/Урагш товч хэвийн ажиллана; нээлттэй дэлгэцийг дахин сонгоход шинээр нээхгүй, тухайн таб руу шилжинэ. Хадгалагдаагүй өөрчлөлттэй табыг хаахад анхааруулна. Таб бүрийн гүйлгэлтийн байрлал хадгалагдана. | E9: /admin/* бүх дэлгэц | H9: 2026-09-10
A10: 4 | B10: Харилцаа | C10: Чат — эмч хоорондын ба эмч–үйлчлүүлэгчийн шууд харилцаа | D10: Бүх дэлгэцийн баруун доод буланд байрлана. Хоёр хүний болон бүлгийн яриа, эмчийн лавлахаас хайх, файл хавсаргах, бичиж байгааг харуулах, уншсан тэмдэглэгээ, уншаагүй мессежийн тоо, компьютерийн мэдэгдэл. Эмч–үйлчлүүлэгчийн харилцаа дэмжинэ. Ярианы эзэн нь баталгаажсан токеноос тодорхойлогддог тул хэн ч өөр хүний яриаг нээх боломжгүй. ТОДРУУЛГА: энэ нь хиймэл оюуны робот (chatbot) биш, хүн хүнтэйгээ харилцах суваг юм. | E10: Бүх дэлгэц — баруун доод булан | H10: 2026-09-10
A11: 5 | B11: UI / UX | C11: Нэгдсэн дизайн систем | D11: Үсгийн хэмжээ, өнгө, зай, булангийн радиус, сүүдэр зэрэг нь нэг эх сурвалжаас удирдагддаг болов. Creative Tim загварын ягаан өнгийг ЗСҮТ-ийн цэнхэр өнгөөр бүрэн сольсон. Уншигдах чанарын шаардлагыг (WCAG AA) хангахын тулд үсгэнд гүн цэнхэр, зөвхөн чимэглэлд цайвар цэнхэр хэрэглэнэ — эмч ээлжийн турш эдгээр дэлгэцийг уншдаг. | E11: Бүх дэлгэц | H11: 2026-09-10
A12: 6 | B12: UI / UX | C12: Хажуугийн цэс ба дээд самбар шинэчлэгдэв | D12: Хажуугийн цэс байгууллагын өнгөний шилжилт дээр буусан, идэвхтэй мөр цэнхэр зураасаар тэмдэглэгдэнэ. Дээд самбар 60 цэгийн өндөртэй, товч бүр ижил 36 цэгийн хэмжээтэй болов; хэл солих туг, тусламжийн товч, хэрэглэгчийн цэс, багтахгүй бол нэмэлт цэс гарна. | E12: Бүх дэлгэц | H12: 2026-09-10
A13: 7 | B13: UI / UX | C13: Эмчийн нүүр хуудас (Зөвлөгөө) шинэчлэгдэв | D13: Тасалбарын урсгал бүтэн өргөнөөр харагдана: шүүлтүүр, шинэ тасалбар бичих талбар, хариултын салбар, зураг томруулж харах, баруун талд статистикийн багана. Өмнөх хувилбарт тасалбарын жагсаалт нарийн баганад шахагдаж, хариултууд нэг дор харагддаггүй байв. | E13: https://mncardio.itsystem.mn/admin/AdviceHome | H13: 2026-09-10
A14: 8 | B14: Маягт | C14: 11 маягтын дэлгэц, CRUD, валидац | D14: Маягт 1.1, 1.2, 1.3, 1.5, 1.6, 1.7, 1.8, 1.9, 2.1, 2.2, 3.1 — нийт 1,687 талбар ачаалагдаж, нэмэх, засах, устгах, хадгалах, заавал бөглөх талбарын шалгалт ажиллаж байна. Хэсэг бүрээр хадгалах, бөглөлтийн явц харуулах, хэсгийг эвхэх, өмнөх процедурын өгөгдлийг хуулах эсэхийг асуух, давтагдах хүснэгтэн талбар ажиллана. | E14: /admin/TenderForm1_1 … 3_1 | F14: #23–#94 | H14: 2026-09-10
A15: 9 | B15: Маягт | C15: Маягтын нэгдсэн бүртгэл, хайлт, экспорт | D15: Бүх маягт нэг цэснээс нээгдэнэ. Маягтын төрөл, регистрийн дугаар, эмч, огноогоор хайна; Excel болон текст (.txt) хэлбэрээр татна; мөр тус бүрээс шууд хэвлэх, баталгаажуулж түгжих боломжтой. Хурд: 50,002 мөр дээр хайлт 254 мс, хуудаслалт 21 мс — тендерийн 3 секундын шалгуурт багтав. | E15: https://mncardio.itsystem.mn/admin/TenderFormAll | F15: #101–#103 | H15: 2026-09-10
A16: 10 | B16: Тайлан | C16: ЗСӨ-ийн хүснэгтэн тайлангийн эрэмбэ зассан | D16: 55 баганатай үзлэгийн тайлан хамгийн хуучин бичлэгээс эхэлж эрэмбэлдэг байсныг эсрэгээр болгов. Их-Уул сумын ЭМТ дээр 790 мөрөөс шинэ хоёр үзлэг 781, 782-р байрлалд буюу 8-р хуудсанд унасан байсан — эмч шинэ үзлэгээ олохын тулд сүүлийн хуудас руу орох шаардлагатай байв. Өгөгдөл хөндөгдөөгүй, зөвхөн буцаах дараалал өөрчлөгдсөн; буцаах скрипт бэлэн. | E16: https://mncardio.itsystem.mn/admin/CVDMonitoringReportList | H16: 2026-09-10
A17: 11 | B17: Иргэний хэсэг | C17: Иргэний хэсгийн нүүр хуудас | D17: Иргэн өөрийн сүүлийн даралт, судасны цохилт, жин, эмчийн хариу, сүүлийн тэмдэглэл, эмчийн зөвлөгөөгөө нэг дэлгэцээс харна. Хэсэг бүр тусдаа ачаалагддаг тул нэг удаан хүсэлт бүх дэлгэцийг хоослохгүй. Үйлчилгээний давхарга (/api/patient) ямар ч тохиолдолд үйлчлүүлэгчийн дугаарыг хүсэлтээс авдаггүй — зөвхөн баталгаажсан токеноос тодорхойлно. ТЭМДЭГЛЭЛ: энэ тайланг бэлтгэх явцад иргэний хэсэг зарим хөтөч дээр англи хэлээр гарч байсныг илрүүлж, монгол хэлийг үндсэн хэл болгож зассан — нэвтрүүлэлт хүлээгдэж байна. | E17: https://mncardio.itsystem.mn/patient/PatientHome | F17: #104 | H17: 2026-09-10
A18: 12 | B18: Иргэний хэсэг | C18: Гар утас, таблетад тохирсон болов | D18: 600 цэгээс нарийн дэлгэц дээр бүртгэлийн жагсаалт хүснэгтийн оронд карт хэлбэрээр гарна — өмнө нь баганын өргөн тогтмол цэгээр өгөгдсөн тул жагсаалт 900–1500 цэг болж, утсан дээр ашиглах боломжгүй байв. Дэлгэцийн хэмжээний шалгуур нэг эх сурвалжаас удирдагдана. Гол зорилтот төхөөрөмж нь эмчийн гартаа барьж явдаг босоо байрлалтай таблет. | E18: Утсаар: /admin/CVDMonitoringList | H18: 2026-09-10
A19: 13 | B19: Хэвлэлт | C19: A4 / PDF хэвлэлт — бүх маягтад нэгдсэн үүсгэгч | D19: Маягтын толь бичгээр удирдагддаг тул шинэ маягт нэмэхэд хэвлэлт нэмэлт кодгүйгээр ажиллана. Хоосон болон бөглөсөн хувилбар гарна; бөглөөгүй нөхцөлт талбар нуугдана; шалгах хуудас Тийм / Үгүй / Тодорхойгүй нүдэн хүснэгтээр, титэм судасны 19 сегмент нэг хүснэгтээр хэвлэгдэнэ. Дэлгэц дээр харж байгаа хувилбар нь принтерээс гарах хувилбартай яг ижил. Батлагдсан цаасан маягттай эцсийн тулгалт эх хувь ирсний дараа хийгдэнэ (мөр #3). | E19: Маягтын дэлгэц → Хэвлэх | F19: #27, #33, #39 … | H19: 2026-09-10
A20: 14 | B20: Хэвлэлт | C20: Эмчийн үзлэгийн бүртгэл АМ-1Б (А/611) хэвлэлт | D20: Эрүүл мэндийн сайдын 2019 оны А/611 дүгээр тушаалын арваннэгдүгээр хавсралтын бүтцээр хэвлэгдэнэ: хүснэгтийн толгойг тендерийн зурган хавсралтаас сэргээж, баганын дугаарлалтыг А, Б, 1–22 болгож, шинэ 5 талбарыг холбов. Өмнө нь 2013 оны 450 тоот тушаалын хуучин бүтэц байсан тул эдгээр талбар хэвлэгдэх байргүй байв. Хөндлөн (landscape) чиглэлээр 22 багана нэг A4-т бүтэн багтана. | E20: https://mncardio.itsystem.mn/admin/ExamRegisterAM1B | F20: #99 | H20: 2026-09-10
A21: 15 | B21: Хэвлэлт | C21: Эх сурвалжийн тэмдэглэгээ бүх хэвлэлт, экспортод | D21: Хуудасны доод хэсэгт байгууллага, мэдээллийн сан, огноо, хэвлэсэн хэрэглэгч, хуудасны дугаар гарна. Тайлан хэвлэдэг 19 контроллерын 18 нь нэгдсэн үүсгэгчид шилжсэн — өмнө нь тус бүр өөрийн хөтчийн процесс асаадаг байв. Мөн тайлан бүр давхцахгүй файлын нэртэй болов: өмнө нь тогтмол нэр ашигладаг байсан тул нэгэн зэрэг хэвлэсэн хоёр эмчийн файл дарж бичигдэж, нөгөө эмчлүүлэгчийн тайлан буруу хүнд очих эрсдэлтэй байв. | E21: Аль ч тайлангийн доод хэсэг | F21: #103 | H21: 2026-09-10
A22: 16 | B22: Интеграц | C22: Мобайл аппликэйшны үйлчилгээний давхарга нээгдэв | D22: Эмчийн модульд 12 маршрут (/api/doctor — миний үзлэгүүд, хяналт, зөвлөгөө, тайлангийн хураангуй, үйлчлүүлэгчид), үйлчлүүлэгчийн модульд 16 маршрут (/api/patient — бүртгэл, тэмдэглэл, асуулт, зөвлөгөө, эрсдэл, цахим үзлэг, сэргээн засах). Бодит HTTP төлөвийн код, жигд бүрхүүлтэй. Гэрээний бүрэн тодорхойлолт: mobile/API.md. | E22: Хүлээлгэн өгөх баримт бичиг: API-ийн тодорхойлолт | F22: #129, #130 | H22: 2026-09-10
A23: 17 | B23: Аюулгүй байдал | C23: Дотоод шалгалтаар илэрсэн 13 зөрчлийн 12 зассан | D23: Зассан: нууц үг ил хадгалагдах, үйлчлүүлэгчийн нууц үгэнд нарийвчлалын шалгуур байхгүй, файл татахад эзэмшлийн шалгалт байхгүй, татгалзсан файлыг «амжилттай» гэж хариулах, байхгүй мөрийг устгахад амжилт гэж хариулах, Excel экспорт хязгааргүй санах ой зарцуулах, гадаад дуудлагад хугацааны хязгаар байхгүй, зэрэг. Үлдсэн 1: /api/base, /api/report, /api/Test токенгүй нээлттэй байгааг одоо байгаа дуудагчид тасалдах эрсдэлтэй тул захиалагчийн шийдвэрээр аюулгүй байдлын аудитад шилжүүлэв (мөр #135). | E23: Гүйцэтгэгчийн дотоод шалгалтын тайлан | F23: #136, #138 | H23: 2026-09-10
A24: 18 | B24: Тест | C24: Автомат туршилтын багц ажиллаж байна | D24: 248 маршрут, 48 бичих урсгал, хөтчөөр 72 шалгуур автоматаар шалгагдана. Ажиллуулах бүрд тайлан, дэлгэцийн зураг үүснэ. Энэ нь гүйцэтгэгчийн дотоод хяналт бөгөөд гэрээгээр хүлээлгэн өгөх албан ёсны тестийн тайлан биш — түүнийг тусад нь бэлтгэнэ (мөр #139). | E24: Гүйцэтгэгчийн дотоод шалгалтын тайлан | F24: #132, #139 | H24: 2026-09-10
A26: Б. ЗАХИАЛАГЧААС ШААРДЛАГАТАЙ — ЗСҮТ. Эдгээргүйгээр дараах ажил үргэлжлэхгүй
A27: 19 | B27: Интеграц | C27: ХУР систем — гэрээ, хандах эрх, түлхүүр, техникийн баримт бичиг | D27: Иргэний бүртгэл, лавлагааны мэдээлэл татах ажил бүхэлдээ зогссон. Хандах эрх, түлхүүргүйгээр хөгжүүлэлт эхлэх ч, туршилт хийх ч боломжгүй тул мөр #109, #110 «Эхлээгүй» биш «Саатсан» төлөвт байна. 2026-09-09-ний захидлын 6-р зүйлээр хүсэлт гаргасан, хариу хүлээгдэж байна. | E27: ЗСҮТ | F27: #108, #109, #110 | G27: ЯАРАЛТАЙ | H27: 2026-09-15
A28: 20 | B28: Интеграц | C28: Тоон гарын үсэг (ДАН / ЦГҮ) — үйлчилгээний гэрээ | D28: Маягт, дүгнэлтийг цахим гарын үсгээр баталгаажуулах ажил зогссон. Гэрээ байгуулаагүй тул мөр #115, #116 «Саатсан». 2026-09-09-ний захидлын 7-р зүйлээр хүсэлт гаргасан, хариу хүлээгдэж байна. | E28: ЗСҮТ | F28: #114, #115, #116 | G28: ЯАРАЛТАЙ | H28: 2026-09-15
A29: 21 | B29: Интеграц | C29: Эмийн жорын систем — гэрээ, хандах эрх, техникийн баримт бичиг | D29: АНХААРУУЛГА: энэ сервисийн хандах эрхийг 2026-09-09-ний захидалд ОРУУЛААГҮЙ. Дараагийн албан бичигт заавал тусгах шаардлагатай, эс бөгөөс хугацаа улам хойшилно. | E29: ЗСҮТ | F29: #111, #112, #113 | G29: Өндөр | H29: 2026-09-15
A30: 22 | B30: Интеграц | C30: Дүрс оношилгоо (PACS / DICOM) — гэрээ, хандах эрх, техникийн баримт бичиг | D30: АНХААРУУЛГА: 2026-09-09-ний захидалд ОРУУЛААГҮЙ. Дараагийн албан бичигт нэмж тусгах шаардлагатай. | E30: ЗСҮТ | F30: #117, #118, #119 | G30: Өндөр | H30: 2026-09-15
A31: 23 | B31: Интеграц | C31: Лабораторийн систем (LIS / HL7) — гэрээ, хандах эрх, техникийн баримт бичиг | D31: АНХААРУУЛГА: 2026-09-09-ний захидалд ОРУУЛААГҮЙ. Дараагийн албан бичигт нэмж тусгах шаардлагатай. | E31: ЗСҮТ | F31: #120, #121, #122 | G31: Өндөр | H31: 2026-09-15
A32: 24 | B32: Интеграц | C32: Эрүүл мэндийн даатгал (ЭМД) — гэрээ, хандах эрх, техникийн баримт бичиг | D32: АНХААРУУЛГА: 2026-09-09-ний захидалд ОРУУЛААГҮЙ. Дараагийн албан бичигт нэмж тусгах шаардлагатай. | E32: ЗСҮТ | F32: #123, #124, #125 | G32: Өндөр | H32: 2026-09-15
A33: 25 | B33: Интеграц | C33: ЭМХТ нэгдсэн систем (А/611) — гэрээ, хандах эрх, техникийн баримт бичиг | D33: АНХААРУУЛГА: 2026-09-09-ний захидалд ОРУУЛААГҮЙ. Маягт 4.1 (АМ-1Б)-ийн хэвлэлт бэлэн болсон тул зөвхөн сервисийн гэрээ, баримт бичиг дутагдаж байна — өөрөөр хэлбэл энэ интеграц техникийн талаасаа хамгийн бэлэн нь боловч гэрээгүйн улмаас эхэлж чадахгүй байна. | E33: ЗСҮТ | F33: #126, #127, #128 | G33: Өндөр | H33: 2026-09-15
A34: 26 | B34: Гэрээ | C34: Маягт 1.4 ба 1.10-ын хамрах хүрээ | D34: Хоёр маягт «Гэрээ байгуулах үед тусгагдана» гэж бүртгэгдсэн бөгөөд хамрах хүрээ өнөөг хүртэл тодорхойгүй байна. Хамрах хүрээ тодорхой болтол хугацаа тавих боломжгүй. 2026-09-09-ний захидлын 4-р зүйл. | E34: ЗСҮТ | F34: #41–#43, #74–#76 | G34: Өндөр | H34: 2026-09-15
A35: 27 | B35: Маягт | C35: Талбарын толь бичгийн эмнэлзүйн баталгаажуулалт | D35: 11 маягтын 1,687 талбарын нэр, төрөл, сонголтын жагсаалт, заавал бөглөх эсэхийг эмнэлзүйн баг хянаж батлах шаардлагатай. Талбарын төрөл нь тендерийн эхээс гаргалгаагаар тодорхойлогдсон тул зарим нь буруу гарсан. Нийт 1,687 талбарын ердөө 5 нь заавал бөглөх гэж тэмдэглэгдсэн байсан тул валидац хийх зүйл бараг байхгүй байв. Нэмж, хуучин бүртгэлийн маягтуудад нэр (Label) дутуу 259 талбар илэрсэн тул тусад нь баталгаажуулах хүснэгт бэлтгэсэн: «МнКардио_талбарын_нэр_баталгаажуулалт.xlsx». Захидлын 2, 3-р зүйл. | E35: ЗСҮТ — эмнэлзүйн баг | F35: #19, #23, #29 … | G35: ЯАРАЛТАЙ | H35: 2026-09-15
A36: 28 | B36: Маягт | C36: 12 маягтын батлагдсан цаасан хувилбар | D36: Хүлээн авах шалгуурын 5 дахь нөхцөл нь «хэвлэх хувилбар батлагдсан цаасан маягттай бүтцээрээ ижил байх» юм. Эх хувь ирээгүй тул хэвлэх маягтын эцсийн тулгалт хийгдэх боломжгүй, улмаар 12 маягтын хүлээн авалт хаагдаж байна. Захидлын 2-р зүйл. | E36: ЗСҮТ | F36: #3 | G36: ЯАРАЛТАЙ | H36: 2026-09-15
A37: 29 | B37: Иргэний хэсэг | C37: ЗСӨ эрсдэлийн үнэлгээний аргачлал | D37: Эрсдэл тооцох аргачлал, томьёо, эрсдэлийн ангиллыг эмнэлзүйн баг батлаагүй. Аргачлалгүйгээр тооцоолуур бичих боломжгүй тул мөр #106, #107 «Саатсан» төлөвт байна. Захидлын 5-р зүйл. | E37: ЗСҮТ — эмнэлзүйн баг | F37: #105, #106, #107 | G37: ЯАРАЛТАЙ | H37: 2026-09-15
A38: 30 | B38: Аюулгүй байдал | C38: Хэрэглэгчийн эрхийн матриц батлах | D38: Эмч, сувилагч, админ, иргэн зэрэг үүрэг тус бүрийн хандах эрх, нууцлалын ангиллыг батлах шаардлагатай. Захидлын 8-р зүйл. | E38: ЗСҮТ | F38: #7 | G38: Өндөр | H38: 2026-09-15
... A42: 34 | B42: Хүлээн авалт | C42: Хүлээлцэх акт | D42: Систем, эх код, баримт бичгийг хүлээлгэн өгөх хоёр талын гарын үсэгтэй акт. Гэрээний хугацаа 2026-09-14-нд дуусах тул дээрх зүйлсийг шийдвэрлэх хугацаа маш богино байна. | E42: ЗСҮТ ба ITsystem | F42: #150 | G42: ЯАРАЛТАЙ | H42: 2026-09-14
A44: ДҮГНЭЛТ. Интеграцын 7 сервисийн 21 мөр бүхэлдээ захиалагчийн гэрээ, техникийн баримт бичгээс хамаарч зогсоод байна — гүйцэтгэгчийн талаас эдгээрт хийх ажил байхгүй. Эдгээрийн 5 нь (эмийн жор, PACS/DICOM, LIS/HL7, ЭМД, ЭМХТ) 2026-09-09-ний захидалд огт ороогүй тул дараагийн албан бичигт заавал тусгах шаардлагатай. Кибер аюулгүй байдлын үнэлгээ, МАБ-ын аудитын захиалга мөн ороогүй бөгөөд эдгээр нь гэрээгээр хүлээлгэн өгөхийн өмнө заавал хийгдэх ажил юм. Захидлаар хүссэн хариуг 2026 оны 09 дүгээр сарын 15-ны дотор өгөхийг хүсэж байна. Гэрээний хугацаа 2026-09-14-нд дуусна.
